Workbook

Sheet Data
A1: درصد پیشرفت کل پروژه | H1: درصد پیشرفت مهندسی | I1: درصد پیشرفت خرید | J1: درصد پیشرفت فونداسیون | K1: درصد پیشرفت ساخت | L1: درصد پیشرفت نصب | M1: درصد پیشرفت سفت کاری | N1: درصد پیشرفت نازک کاری | O1: وضعیت آب و هوا | AC1: وضعیت آب و هوا | AF1: صورت وضعیت | AL1: عملکرد پیمانکاران | AQ1: درصد پیشرفت مهندسی | AS1: درصد پیشرفت خرید | AU1: درصد پیشرفت فونداسیون | AW1: درصد پیشرفت ساخت | AY1: درصد پیشرفت نصب | BA1: درصد پیشرفت سفت کاری | BC1: درصد پیشرفت نازک کاری | BE1: وضعیت HSE
A2: شماره گزارش | B2: تاریخ میلادی | C2: گزارش هفتگی | D2: برنامه ای | E2: واقعی | F2: =Dashboard!A1 -> 131 | G2: lable text | O2: کمترین | V2: بیشترین | AC2: تاریخ | AD2: کمترین | AE2: بیشترین | AF2: شماره | AG2: تاریخ شمسی | AH2: شماره | AI2: ارسالی | AJ2: تاییدی | AK2: اختلاف | AL2: پیمانکار شماره 1 | AM2: پیمانکار شماره 2 | AN2: پیمانکار شماره 3 | AO2: پیمانکار شماره 4 | AP2: پیمانکار شماره 5 | AQ2: واقعی | AR2: برنامه ای | AS2: واقعی | AT2: برنامه ای | AU2: واقعی | AV2: برنامه ای | AW2: واقعی | AX2: برنامه ای | AY2: واقعی | AZ2: برنامه ای | BA2: واقعی | BB2: برنامه ای | BC2: واقعی | BD2: برنامه ای | BE2: شماره | BF2: تاریخ شمسی | BG2: شماره | BH2: پیمانکار 1 | BI2: پیمانکار 2 | BJ2: پیمانکار 3 | BK2: پیمانکار 4
A3: 1 | B3: 43929 | C3: =TEXT(B3,"[$-fa-IR,16]yyyy/mm/dd") -> 1399/01/20 | D3: 0 | E3: 0 | F3: =IF($F$2=A3,E3,NA()) -> #N/A | G3: ="تاریخ: "&C3&CHAR(10)&"درصد پیشرفت برنامه ای: "&ROUND(D3*100,2)&"%"&CHAR(10)&"درصد پیشرفت واقعی: "&ROUND(E3*100,2)&"%" -> تاریخ: 1399/01/20 درصد پیشرفت برنامه ای: 0% درصد پیشرفت واقعی: 0% | H3: 0 | I3: 0 | J3: 0 | K3: 0 | L3: 0 | M3: 0 | N3: 0 | O3: 15 | P3: 16 | Q3: 18 | R3: 18 | S3: 15 | T3: 15 | U3: 14 | V3: =O3+3 -> 18 | W3: =P3+4 -> 20 | X3: =Q3+4 -> 22 | Y3: =R3+1 -> 19 | Z3: =S3+3 -> 18 | AA3: =T3+1 -> 16 | AB3: =U3+5 -> 19 | AC3: =INDEX(B:B,MATCH(F2,A:A,0),1) -> 44839 | AD3: {=TRANSPOSE(INDEX(O:U,MATCH(F2,A:A,0),))} -> 24 | AE3: {=TRANSPOSE(INDEX(V:AB,MATCH(F2,A:A,0),))} -> 27 | AF3: =INDEX(A:G,MATCH(AG3,C:C,0),1) -> 7 | AG3: 1399/02/31 | AH3: 1 | AI3: 15120000000 | AJ3: 15067000000 | AK3: =AI3-AJ3 -> 53000000 | AL3: 0.5 | AM3: 0.62 | AN3: 0.78 | AO3: 0.42 | AP3: 0.8 | AQ3: =H3 -> 0 | AR3: 0.03 | AS3: =I3 -> 0 | AT3: 0 | AU3: =J3 -> 0 | AV3: 0 | AW3: =K3 -> 0 | AX3: 0 | AY3: =L3 -> 0 | AZ3: 0 | BA3: =M3 -> 0 | BB3: 0 | BC3: =N3 -> 0 | BD3: 0 | BE3: 7 | BF3: 1399/02/31 | BG3: 1 | BH3: 0.55 | BI3: 0.55 | BJ3: 0.77 | BK3: 0.45
A4: 2 | B4: 43936 | C4: =TEXT(B4,"[$-fa-IR,16]yyyy/mm/dd") -> 1399/01/27 | D4: 0.013 | E4: 0 | F4: =IF($F$2=A4,E4,NA()) -> #N/A | G4: ="تاریخ: "&C4&CHAR(10)&"درصد پیشرفت برنامه ای: "&ROUND(D4*100,2)&"%"&CHAR(10)&"درصد پیشرفت واقعی: "&ROUND(E4*100,2)&"%" -> تاریخ: 1399/01/27 درصد پیشرفت برنامه ای: 1.3% درصد پیشرفت واقعی: 0% | H4: 0.05 | I4: 0 | J4: 0 | K4: 0 | L4: 0 | M4: 0 | N4: 0 | O4: =U3 -> 14 | P4: 15 | Q4: 15 | R4: 18 | S4: 17 | T4: 18 | U4: 19 | V4: =O4+3 -> 17 | W4: =P4+4 -> 19 | X4: =Q4+4 -> 19 | Y4: =R4+1 -> 19 | Z4: =S4+3 -> 20 | AA4: =T4+1 -> 19 | AB4: =U4+5 -> 24 | AC4: =AC3+1 -> 44840 | AD4: 23 | AE4: 27 | AF4: =INDEX(A:G,MATCH(AG4,C:C,0),1) -> 11 | AG4: 1399/03/28 | AH4: 2 | AI4: 21000000000 | AJ4: 20927000000 | AK4: =AI4-AJ4 -> 73000000 | AL4: 0.6 | AM4: 0.9 | AN4: 0.5 | AO4: 0.5 | AP4: 0.62 | AQ4: =H4 -> 0.05 | AR4: 0.07 | AS4: =I4 -> 0 | AT4: 0 | AU4: =J4 -> 0 | AV4: 0 | AW4: =K4 -> 0 | AX4: 0 | AY4: =L4 -> 0 | AZ4: 0 | BA4: =M4 -> 0 | BB4: 0 | BC4: =N4 -> 0 | BD4: 0 | BE4: 11 | BF4: 1399/03/28 | BG4: 2 | BH4: 0.6 | BI4: 0.6 | BJ4: 0.2 | BK4: 0.52
A5: 3 | B5: 43943 | C5: =TEXT(B5,"[$-fa-IR,16]yyyy/mm/dd") -> 1399/02/03 | D5: 0.018 | E5: 0.00504 | F5: =IF($F$2=A5,E5,NA()) -> #N/A | G5: ="تاریخ: "&C5&CHAR(10)&"درصد پیشرفت برنامه ای: "&ROUND(D5*100,2)&"%"&CHAR(10)&"درصد پیشرفت واقعی: "&ROUND(E5*100,2)&"%" -> تاریخ: 1399/02/03 درصد پیشرفت برنامه ای: 1.8% درصد پیشرفت واقعی: 0.5% | H5: =H4+7% -> 0.12 | I5: 0 | J5: 0 | K5: 0 | L5: 0 | M5: 0 | N5: 0 | O5: =U4 -> 19 | P5: 19 | Q5: 17 | R5: 17 | S5: 19 | T5: 20 | U5: 21 | V5: =O5+3 -> 22 | W5: =P5+4 -> 23 | X5: =Q5+4 -> 21 | Y5: =R5+1 -> 18 | Z5: =S5+3 -> 22 | AA5: =T5+1 -> 21 | AB5: =U5+5 -> 26 | AC5: =AC4+1 -> 44841 | AD5: 24 | AE5: 28 | AF5: =INDEX(A:G,MATCH(AG5,C:C,0),1) -> 15 | AG5: 1399/04/25 | AH5: 3 | AI5: 47880000000 | AJ5: 47712000000 | AK5: =AI5-AJ5 -> 168000000 | AL5: 0.66 | AM5: 0.7 | AN5: 0.8 | AO5: 0.55 | AP5: 0.5 | AQ5: =H5 -> 0.12 | AR5: 0.15 | AS5: =I5 -> 0 | AT5: 0.02 | AU5: =J5 -> 0 | AV5: 0 | AW5: =K5 -> 0 | AX5: 0 | AY5: =L5 -> 0 | AZ5: 0 | BA5: =M5 -> 0 | BB5: 0 | BC5: =N5 -> 0 | BD5: 0 | BE5: 15 | BF5: 1399/04/25 | BG5: 3 | BH5: 0.45 | BI5: 0.45 | BJ5: 0.45 | BK5: 0.62
A6: 4 | B6: 43950 | C6: =TEXT(B6,"[$-fa-IR,16]yyyy/mm/dd") -> 1399/02/10 | D6: 0.027 | E6: 0.00504 | F6: =IF($F$2=A6,E6,NA()) -> #N/A | G6: ="تاریخ: "&C6&CHAR(10)&"درصد پیشرفت برنامه ای: "&ROUND(D6*100,2)&"%"&CHAR(10)&"درصد پیشرفت واقعی: "&ROUND(E6*100,2)&"%" -> تاریخ: 1399/02/10 درصد پیشرفت برنامه ای: 2.7% درصد پیشرفت واقعی: 0.5% | H6: =H5+7% -> 0.19 | I6: 0 | J6: 0 | K6: 0 | L6: 0 | M6: 0 | N6: 0 | O6: =U5 -> 21 | P6: 22 | Q6: 22 | R6: 23 | S6: 21 | T6: 22 | U6: 24 | V6: =O6+3 -> 24 | W6: =P6+4 -> 26 | X6: =Q6+4 -> 26 | Y6: =R6+1 -> 24 | Z6: =S6+3 -> 24 | AA6: =T6+1 -> 23 | AB6: =U6+5 -> 29 | AC6: =AC5+1 -> 44842 | AD6: 23 | AE6: 24 | AF6: =INDEX(A:G,MATCH(AG6,C:C,0),1) -> 19 | AG6: 1399/05/22 | AH6: 4 | AI6: 71400000000 | AJ6: 71150000000 | AK6: =AI6-AJ6 -> 250000000 | AL6: 0.55 | AM6: 0.4 | AN6: 0.4 | AO6: 0.9 | AP6: 0.8 | AQ6: =H6 -> 0.19 | AR6: 0.21 | AS6: =I6 -> 0 | AT6: 0.05 | AU6: =J6 -> 0 | AV6: 0 | AW6: =K6 -> 0 | AX6: 0 | AY6: =L6 -> 0 | AZ6: 0 | BA6: =M6 -> 0 | BB6: 0 | BC6: =N6 -> 0 | BD6: 0 | BE6: 19 | BF6: 1399/05/22 | BG6: 4 | BH6: 0.77 | BI6: 0.52 | BJ6: 0.52 | BK6: 0.64
A7: 5 | B7: 43957 | C7: =TEXT(B7,"[$-fa-IR,16]yyyy/mm/dd") -> 1399/02/17 | D7: 0.036 | E7: 0.00504 | F7: =IF($F$2=A7,E7,NA()) -> #N/A | G7: ="تاریخ: "&C7&CHAR(10)&"درصد پیشرفت برنامه ای: "&ROUND(D7*100,2)&"%"&CHAR(10)&"درصد پیشرفت واقعی: "&ROUND(E7*100,2)&"%" -> تاریخ: 1399/02/17 درصد پیشرفت برنامه ای: 3.6% درصد پیشرفت واقعی: 0.5% | H7: =H6+7% -> 0.26 | I7: 0.03 | J7: 0 | K7: 0 | L7: 0 | M7: 0 | N7: 0 | O7: =U6 -> 24 | P7: 23 | Q7: 24 | R7: 23 | S7: 25 | T7: 25 | U7: 26 | V7: =O7+3 -> 27 | W7: =P7+4 -> 27 | X7: =Q7+4 -> 28 | Y7: =R7+1 -> 24 | Z7: =S7+3 -> 28 | AA7: =T7+1 -> 26 | AB7: =U7+5 -> 31 | AC7: =AC6+1 -> 44843 | AD7: 25 | AE7: 28 | AF7: =INDEX(A:G,MATCH(AG7,C:C,0),1) -> 23 | AG7: 1399/06/19 | AH7: 5 | AI7: 111720000000 | AJ7: 111329000000 | AK7: =AI7-AJ7 -> 391000000 | AL7: 0.7 | AM7: 0.55 | AN7: 0.1 | AO7: 0.4 | AP7: 0.9 | AQ7: =H7 -> 0.26 | AR7: 0.29 | AS7: =I7 -> 0.03 | AT7: =AT6+1.2% -> 0.062 | AU7: =J7 -> 0 | AV7: 0 | AW7: =K7 -> 0 | AX7: 0 | AY7: =L7 -> 0 | AZ7: 0 | BA7: =M7 -> 0 | BB7: 0 | BC7: =N7 -> 0 | BD7: 0 | BE7: 23 | BF7: 1399/06/19 | BG7: 5 | BH7: 0.2 | BI7: 0.62 | BJ7: 0.62 | BK7: 0.65
A8: 6 | B8: 43964 | C8: =TEXT(B8,"[$-fa-IR,16]yyyy/mm/dd") -> 1399/02/24 | D8: 0.045 | E8: 0.00504 | F8: =IF($F$2=A8,E8,NA()) -> #N/A | G8: ="تاریخ: "&C8&CHAR(10)&"درصد پیشرفت برنامه ای: "&ROUND(D8*100,2)&"%"&CHAR(10)&"درصد پیشرفت واقعی: "&ROUND(E8*100,2)&"%" -> تاریخ: 1399/02/24 درصد پیشرفت برنامه ای: 4.5% درصد پیشرفت واقعی: 0.5% | H8: =H7+7% -> 0.33 | I8: =I7+1% -> 0.04 | J8: 0 | K8: 0 | L8: 0 | M8: 0 | N8: 0 | O8: =U7 -> 26 | P8: 25 | Q8: 25 | R8: 26 | S8: 26 | T8: 25 | U8: 25 | V8: =O8+3 -> 29 | W8: =P8+4 -> 29 | X8: =Q8+4 -> 29 | Y8: =R8+1 -> 27 | Z8: =S8+3 -> 29 | AA8: =T8+1 -> 26 | AB8: =U8+5 -> 30 | AC8: =AC7+1 -> 44844 | AD8: 25 | AE8: 26 | AF8: =INDEX(A:G,MATCH(AG8,C:C,0),1) -> 27 | AG8: 1399/07/16 | AH8: 6 | AI8: 140828000000 | AJ8: 140335000000 | AK8: =AI8-AJ8 -> 493000000 | AL8: 0.4 | AM8: 0.69 | AN8: 0.5 | AO8: 0.2 | AP8: 0.4 | AQ8: =H8 -> 0.33 | AR8: 0.39 | AS8: =I8 -> 0.04 | AT8: =AT7+1.2% -> 0.074 | AU8: =J8 -> 0 | AV8: 0 | AW8: =K8 -> 0 | AX8: 0 | AY8: =L8 -> 0 | AZ8: 0 | BA8: =M8 -> 0 | BB8: 0 | BC8: =N8 -> 0 | BD8: 0 | BE8: 27 | BF8: 1399/07/16 | BG8: 6 | BH8: 0.45 | BI8: 0.4 | BJ8: 0.4 | BK8: 0.62
A9: 7 | B9: 43971 | C9: =TEXT(B9,"[$-fa-IR,16]yyyy/mm/dd") -> 1399/02/31 | D9: 0.054 | E9: 0.01008 | F9: =IF($F$2=A9,E9,NA()) -> #N/A | G9: ="تاریخ: "&C9&CHAR(10)&"درصد پیشرفت برنامه ای: "&ROUND(D9*100,2)&"%"&CHAR(10)&"درصد پیشرفت واقعی: "&ROUND(E9*100,2)&"%" -> تاریخ: 1399/02/31 درصد پیشرفت برنامه ای: 5.4% درصد پیشرفت واقعی: 1.01% | H9: =H8+4% -> 0.37 | I9: =I8+1% -> 0.05 | J9: 0 | K9: 0 | L9: 0 | M9: 0 | N9: 0 | O9: =U8 -> 25 | P9: 26 | Q9: 26 | R9: 27 | S9: 28 | T9: 29 | U9: 29 | V9: =O9+3 -> 28 | W9: =P9+4 -> 30 | X9: =Q9+4 -> 30 | Y9: =R9+1 -> 28 | Z9: =S9+3 -> 31 | AA9: =T9+1 -> 30 | AB9: =U9+5 -> 34 | AC9: =AC8+1 -> 44845 | AD9: 26 | AE9: 31 | AF9: =INDEX(A:G,MATCH(AG9,C:C,0),1) -> 31 | AG9: 1399/08/14 | AH9: 7 | AI9: 194882000000 | AJ9: 194200000000 | AK9: =AI9-AJ9 -> 682000000 | AL9: 0.35 | AM9: 0.4 | AN9: 0.9 | AO9: 0.8 | AP9: 0.2 | AQ9: =H9 -> 0.37 | AR9: 0.42 | AS9: =I9 -> 0.05 | AT9: =AT8+1.2% -> 0.086 | AU9: =J9 -> 0 | AV9: 0 | AW9: =K9 -> 0 | AX9: 0 | AY9: =L9 -> 0 | AZ9: 0 | BA9: =M9 -> 0 | BB9: 0 | BC9: =N9 -> 0 | BD9: 0 | BE9: 31 | BF9: 1399/08/14 | BG9: 7 | BH9: 0.52 | BI9: 0.55 | BJ9: 0.55 | BK9: 0.4
A10: 8 | B10: 43978 | C10: =TEXT(B10,"[$-fa-IR,16]yyyy/mm/dd") -> 1399/03/07 | D10: 0.063 | E10: 0.01008 | F10: =IF($F$2=A10,E10,NA()) -> #N/A | G10: ="تاریخ: "&C10&CHAR(10)&"درصد پیشرفت برنامه ای: "&ROUND(D10*100,2)&"%"&CHAR(10)&"درصد پیشرفت واقعی: "&ROUND(E10*100,2)&"%" -> تاریخ: 1399/03/07 درصد پیشرفت برنامه ای: 6.3% درصد پیشرفت واقعی: 1.01% | H10: =H9+4% -> 0.41 | I10: =I9+1% -> 0.06 | J10: 0 | K10: 0 | L10: 0 | M10: 0 | N10: 0 | O10: =U9 -> 29 | P10: 29 | Q10: 28 | R10: 29 | S10: 30 | T10: 31 | U10: 30 | V10: =O10+3 -> 32 | W10: =P10+4 -> 33 | X10: =Q10+4 -> 32 | Y10: =R10+1 -> 30 | Z10: =S10+3 -> 33 | AA10: =T10+1 -> 32 | AB10: =U10+5 -> 35 | AF10: =INDEX(A:G,MATCH(AG10,C:C,0),1) -> 35 | AG10: 1399/09/12 | AH10: 8 | AI10: 250437000000 | AJ10: 249560000000 | AK10: =AI10-AJ10 -> 877000000 | AL10: 0.85 | AM10: 0.8 | AN10: 0.5 | AO10: 0.6 | AP10: 0.6 | AQ10: =H10 -> 0.41 | AR10: 0.48 | AS10: =I10 -> 0.06 | AT10: =AT9+1.2% -> 0.098 | AU10: =J10 -> 0 | AV10: 0 | AW10: =K10 -> 0 | AX10: 0 | AY10: =L10 -> 0 | AZ10: 0 | BA10: =M10 -> 0 | BB10: 0 | BC10: =N10 -> 0 | BD10: 0 | BE10: 35 | BF10: 1399/09/12 | BG10: 8 | BH10: 0.62 | BI10: 0.6 | BJ10: 0.6 | BK10: 0.55
A11: 9 | B11: 43985 | C11: =TEXT(B11,"[$-fa-IR,16]yyyy/mm/dd") -> 1399/03/14 | D11: 0.072 | E11: 0.01008 | F11: =IF($F$2=A11,E11,NA()) -> #N/A | G11: ="تاریخ: "&C11&CHAR(10)&"درصد پیشرفت برنامه ای: "&ROUND(D11*100,2)&"%"&CHAR(10)&"درصد پیشرفت واقعی: "&ROUND(E11*100,2)&"%" -> تاریخ: 1399/03/14 درصد پیشرفت برنامه ای: 7.2% درصد پیشرفت واقعی: 1.01% | H11: =H10+4% -> 0.45 | I11: =I10+1% -> 0.07 | J11: 0 | K11: 0 | L11: 0 | M11: 0 | N11: 0 | O11: =U10 -> 30 | P11: 25 | Q11: 25 | R11: 26 | S11: 26 | T11: 25 | U11: 25 | V11: =O11+3 -> 33 | W11: =P11+4 -> 29 | X11: =Q11+4 -> 29 | Y11: =R11+1 -> 27 | Z11: =S11+3 -> 29 | AA11: =T11+1 -> 26 | AB11: =U11+5 -> 30 | AF11: =INDEX(A:G,MATCH(AG11,C:C,0),1) -> 39 | AG11: 1399/10/10 | AH11: 9 | AI11: 310497000000 | AJ11: 309410000000 | AK11: =AI11-AJ11 -> 1087000000 | AL11: 0.9 | AM11: 0.95 | AN11: 0.8 | AO11: 0.7 | AP11: 0.1 | AQ11: =H11 -> 0.45 | AR11: 0.49 | AS11: =I11 -> 0.07 | AT11: =AT10+1.2% -> 0.11 | AU11: =J11 -> 0 | AV11: 0.03 | AW11: =K11 -> 0 | AX11: 0 | AY11: =L11 -> 0 | AZ11: 0 | BA11: =M11 -> 0 | BB11: 0 | BC11: =N11 -> 0 | BD11: 0 | BE11: 39 | BF11: 1399/10/10 | BG11: 9 | BH11: 0.64 | BI11: 0.45 | BJ11: 0.45 | BK11: 0.6
A12: 10 | B12: 43992 | C12: =TEXT(B12,"[$-fa-IR,16]yyyy/mm/dd") -> 1399/03/21 | D12: 0.081 | E12: 0.014 | F12: =IF($F$2=A12,E12,NA()) -> #N/A | G12: ="تاریخ: "&C12&CHAR(10)&"درصد پیشرفت برنامه ای: "&ROUND(D12*100,2)&"%"&CHAR(10)&"درصد پیشرفت واقعی: "&ROUND(E12*100,2)&"%" -> تاریخ: 1399/03/21 درصد پیشرفت برنامه ای: 8.1% درصد پیشرفت واقعی: 1.4% | H12: =H11+4% -> 0.49 | I12: =I11+1% -> 0.08 | J12: 0 | K12: 0 | L12: 0 | M12: 0 | N12: 0 | O12: =U11 -> 25 | P12: 26 | Q12: 26 | R12: 27 | S12: 28 | T12: 29 | U12: 29 | V12: =O12+3 -> 28 | W12: =P12+4 -> 30 | X12: =Q12+4 -> 30 | Y12: =R12+1 -> 28 | Z12: =S12+3 -> 31 | AA12: =T12+1 -> 30 | AB12: =U12+5 -> 34 | AF12: =INDEX(A:G,MATCH(AG12,C:C,0),1) -> 43 | AG12: 1399/11/08 | AH12: 10 | AI12: 355542000000 | AJ12: 354298000000 | AK12: =AI12-AJ12 -> 1244000000 | AL12: 0.7 | AM12: 0.68 | AN12: 0.5 | AO12: 0.9 | AP12: 0.55 | AQ12: =H12 -> 0.49 | AR12: 0.52 | AS12: =I12 -> 0.08 | AT12: =AT11+1.2% -> 0.122 | AU12: =J12 -> 0 | AV12: 0.05 | AW12: =K12 -> 0 | AX12: 0 | AY12: =L12 -> 0 | AZ12: 0 | BA12: =M12 -> 0 | BB12: 0 | BC12: =N12 -> 0 | BD12: 0 | BE12: 43 | BF12: 1399/11/08 | BG12: 10 | BH12: 0.65 | BI12: 0.77 | BJ12: 0.77 | BK12: 0.45
A13: 11 | B13: 43999 | C13: =TEXT(B13,"[$-fa-IR,16]yyyy/mm/dd") -> 1399/03/28 | D13: 0.09 | E13: 0.014 | F13: =IF($F$2=A13,E13,NA()) -> #N/A | G13: ="تاریخ: "&C13&CHAR(10)&"درصد پیشرفت برنامه ای: "&ROUND(D13*100,2)&"%"&CHAR(10)&"درصد پیشرفت واقعی: "&ROUND(E13*100,2)&"%" -> تاریخ: 1399/03/28 درصد پیشرفت برنامه ای: 9% درصد پیشرفت واقعی: 1.4% | H13: =H12+4% -> 0.53 | I13: =I12+1% -> 0.09 | J13: 0 | K13: 0 | L13: 0 | M13: 0 | N13: 0 | O13: =U12 -> 29 | P13: 29 | Q13: 28 | R13: 29 | S13: 30 | T13: 31 | U13: 30 | V13: =O13+3 -> 32 | W13: =P13+4 -> 33 | X13: =Q13+4 -> 32 | Y13: =R13+1 -> 30 | Z13: =S13+3 -> 33 | AA13: =T13+1 -> 32 | AB13: =U13+5 -> 35 | AF13: =INDEX(A:G,MATCH(AG13,C:C,0),1) -> 47 | AG13: 1399/12/06 | AH13: 11 | AI13: 409596000000 | AJ13: 408162000000 | AK13: =AI13-AJ13 -> 1434000000 | AL13: 0.6 | AM13: 0.5 | AN13: 0.66 | AO13: 0.5 | AP13: 0.9 | AQ13: =H13 -> 0.53 | AR13: 0.59 | AS13: =I13 -> 0.09 | AT13: =AT12+1.2% -> 0.134 | AU13: =J13 -> 0 | AV13: 0.07 | AW13: =K13 -> 0 | AX13: 0 | AY13: =L13 -> 0 | AZ13: 0 | BA13: =M13 -> 0 | BB13: 0 | BC13: =N13 -> 0 | BD13: 0 | BE13: 47 | BF13: 1399/12/06 | BG13: 11 | BH13: 0.62 | BI13: 0.4 | BJ13: 0.4 | BK13: 0.77
A14: 12 | B14: 44006 | C14: =TEXT(B14,"[$-fa-IR,16]yyyy/mm/dd") -> 1399/04/04 | D14: 0.099 | E14: 0.01904 | F14: =IF($F$2=A14,E14,NA()) -> #N/A | G14: ="تاریخ: "&C14&CHAR(10)&"درصد پیشرفت برنامه ای: "&ROUND(D14*100,2)&"%"&CHAR(10)&"درصد پیشرفت واقعی: "&ROUND(E14*100,2)&"%" -> تاریخ: 1399/04/04 درصد پیشرفت برنامه ای: 9.9% درصد پیشرفت واقعی: 1.9% | H14: =H13+4% -> 0.57 | I14: =I13+1% -> 0.1 | J14: 0 | K14: 0 | L14: 0 | M14: 0 | N14: 0 | O14: =U13 -> 30 | P14: 31 | Q14: 31 | R14: 32 | S14: 31 | T14: 33 | U14: 30 | V14: =O14+3 -> 33 | W14: =P14+4 -> 35 | X14: =Q14+4 -> 35 | Y14: =R14+1 -> 33 | Z14: =S14+3 -> 34 | AA14: =T14+1 -> 34 | AB14: =U14+5 -> 35 | AF14: =INDEX(A:G,MATCH(AG14,C:C,0),1) -> 51 | AG14: 1400/01/04 | AH14: 12 | AI14: 446528000000 | AJ14: 444965000000 | AK14: =AI14-AJ14 -> 1563000000 | AL14: 0.55 | AM14: 0.62 | AN14: 0.78 | AO14: 0.42 | AP14: 0.8 | AQ14: =H14 -> 0.57 | AR14: 0.63 | AS14: =I14 -> 0.1 | AT14: =AT13+1.2% -> 0.146 | AU14: =J14 -> 0 | AV14: =AV13+1.8% -> 0.088 | AW14: =K14 -> 0 | AX14: 0 | AY14: =L14 -> 0 | AZ14: 0 | BA14: =M14 -> 0 | BB14: 0 | BC14: =N14 -> 0 | BD14: 0 | BE14: 51 | BF14: 1400/01/04 | BG14: 12 | BH14: 0.4 | BI14: 0.55 | BJ14: 0.55 | BK14: 0.2
A15: 13 | B15: 44013 | C15: =TEXT(B15,"[$-fa-IR,16]yyyy/mm/dd") -> 1399/04/11 | D15: 0.108 | E15: 0.02408 | F15: =IF($F$2=A15,E15,NA()) -> #N/A | G15: ="تاریخ: "&C15&CHAR(10)&"درصد پیشرفت برنامه ای: "&ROUND(D15*100,2)&"%"&CHAR(10)&"درصد پیشرفت واقعی: "&ROUND(E15*100,2)&"%" -> تاریخ: 1399/04/11 درصد پیشرفت برنامه ای: 10.8% درصد پیشرفت واقعی: 2.41% | H15: =H14+4% -> 0.61 | I15: =I14+1% -> 0.11 | J15: 0 | K15: 0 | L15: 0 | M15: 0 | N15: 0 | O15: =U14 -> 30 | P15: 32 | Q15: 33 | R15: 34 | S15: 32 | T15: 35 | U15: 34 | V15: =O15+3 -> 33 | W15: =P15+4 -> 36 | X15: =Q15+4 -> 37 | Y15: =R15+1 -> 35 | Z15: =S15+3 -> 35 | AA15: =T15+1 -> 36 | AB15: =U15+5 -> 39 | AF15: =INDEX(A:G,MATCH(AG15,C:C,0),1) -> 55 | AG15: 1400/02/01 | AH15: 13 | AI15: 441140000000 | AJ15: 439596000000 | AK15: =AI15-AJ15 -> 1544000000 | AL15: 0.6 | AM15: 0.9 | AN15: 0.5 | AO15: 0.5 | AP15: 0.62 | AQ15: =H15 -> 0.61 | AR15: 0.67 | AS15: =I15 -> 0.11 | AT15: =AT14+1.6% -> 0.162 | AU15: =J15 -> 0 | AV15: =AV14+1.8% -> 0.106 | AW15: =K15 -> 0 | AX15: 0 | AY15: =L15 -> 0 | AZ15: 0 | BA15: =M15 -> 0 | BB15: 0 | BC15: =N15 -> 0 | BD15: 0 | BE15: 55 | BF15: 1400/02/01 | BG15: 13 | BH15: 0.55 | BI15: 0.6 | BJ15: 0.6 | BK15: 0.45
A16: 14 | B16: 44020 | C16: =TEXT(B16,"[$-fa-IR,16]yyyy/mm/dd") -> 1399/04/18 | D16: 0.115 | E16: 0.028 | F16: =IF($F$2=A16,E16,NA()) -> #N/A | G16: ="تاریخ: "&C16&CHAR(10)&"درصد پیشرفت برنامه ای: "&ROUND(D16*100,2)&"%"&CHAR(10)&"درصد پیشرفت واقعی: "&ROUND(E16*100,2)&"%" -> تاریخ: 1399/04/18 درصد پیشرفت برنامه ای: 11.5% درصد پیشرفت واقعی: 2.8% | H16: =H15+2% -> 0.63 | I16: 0.11 | J16: 0 | K16: 0 | L16: 0 | M16: 0 | N16: 0 | O16: =U15 -> 34 | P16: 36 | Q16: 37 | R16: 36 | S16: 38 | T16: 36 | U16: 36 | V16: =O16+3 -> 37 | W16: =P16+4 -> 40 | X16: =Q16+4 -> 41 | Y16: =R16+1 -> 37 | Z16: =S16+3 -> 41 | AA16: =T16+1 -> 37 | AB16: =U16+5 -> 41 | AF16: =INDEX(A:G,MATCH(AG16,C:C,0),1) -> 59 | AG16: 1400/02/29 | AH16: 14 | AI16: 472364000000 | AJ16: 470711000000 | AK16: =AI16-AJ16 -> 1653000000 | AL16: 0.66 | AM16: 0.7 | AN16: 0.8 | AO16: 0.55 | AP16: 0.5 | AQ16: =H16 -> 0.63 | AR16: 0.7 | AS16: =I16 -> 0.11 | AT16: =AT15+1.6% -> 0.178 | AU16: =J16 -> 0 | AV16: =AV15+1.8% -> 0.124 | AW16: =K16 -> 0 | AX16: 0 | AY16: =L16 -> 0 | AZ16: 0 | BA16: =M16 -> 0 | BB16: 0 | BC16: =N16 -> 0 | BD16: 0 | BE16: 59 | BF16: 1400/02/29 | BG16: 14 | BH16: 0.6 | BI16: 0.45 | BJ16: 0.45 | BK16: 0.52
A17: 15 | B17: 44027 | C17: =TEXT(B17,"[$-fa-IR,16]yyyy/mm/dd") -> 1399/04/25 | D17: 0.122 | E17: 0.03192 | F17: =IF($F$2=A17,E17,NA()) -> #N/A | G17: ="تاریخ: "&C17&CHAR(10)&"درصد پیشرفت برنامه ای: "&ROUND(D17*100,2)&"%"&CHAR(10)&"درصد پیشرفت واقعی: "&ROUND(E17*100,2)&"%" -> تاریخ: 1399/04/25 درصد پیشرفت برنامه ای: 12.2% درصد پیشرفت واقعی: 3.19% | H17: =H16+2% -> 0.65 | I17: 0.11 | J17: =I7 -> 0.03 | K17: 0 | L17: 0 | M17: 0 | N17: 0 | O17: =U16 -> 36 | P17: 38 | Q17: 39 | R17: 40 | S17: 39 | T17: 40 | U17: 39 | V17: =O17+3 -> 39 | W17: =P17+4 -> 42 | X17: =Q17+4 -> 43 | Y17: =R17+1 -> 41 | Z17: =S17+3 -> 42 | AA17: =T17+1 -> 41 | AB17: =U17+5 -> 44 | AF17: =INDEX(A:G,MATCH(AG17,C:C,0),1) -> 63 | AG17: 1400/03/26 | AH17: 15 | AI17: 549253000000 | AJ17: 547331000000 | AK17: =AI17-AJ17 -> 1922000000 | AL17: 0.55 | AM17: 0.4 | AN17: 0.4 | AO17: 0.9 | AP17: 0.8 | AQ17: =H17 -> 0.65 | AR17: 0.74 | AS17: =I17 -> 0.11 | AT17: =AT16+1.6% -> 0.194 | AU17: =J17 -> 0.03 | AV17: =AV16+1.8% -> 0.142 | AW17: =K17 -> 0 | AX17: 0 | AY17: =L17 -> 0 | AZ17: 0 | BA17: =M17 -> 0 | BB17: 0 | BC17: =N17 -> 0 | BD17: 0 | BE17: 63 | BF17: 1400/03/26 | BG17: 15 | BH17: 0.45 | BI17: 0.4 | BJ17: 0.52 | BK17: 0.62
A18: 16 | B18: 44034 | C18: =TEXT(B18,"[$-fa-IR,16]yyyy/mm/dd") -> 1399/05/01 | D18: 0.129 | E18: 0.03584 | F18: =IF($F$2=A18,E18,NA()) -> #N/A | G18: ="تاریخ: "&C18&CHAR(10)&"درصد پیشرفت برنامه ای: "&ROUND(D18*100,2)&"%"&CHAR(10)&"درصد پیشرفت واقعی: "&ROUND(E18*100,2)&"%" -> تاریخ: 1399/05/01 درصد پیشرفت برنامه ای: 12.9% درصد پیشرفت واقعی: 3.58% | H18: =H17+2% -> 0.67 | I18: 0.11 | J18: =I8 -> 0.04 | K18: 0 | L18: 0 | M18: 0 | N18: 0 | O18: =U17 -> 39 | P18: 40 | Q18: 41 | R18: 40 | S18: 42 | T18: 43 | U18: 42 | V18: =O18+3 -> 42 | W18: =P18+4 -> 44 | X18: =Q18+4 -> 45 | Y18: =R18+1 -> 41 | Z18: =S18+3 -> 45 | AA18: =T18+1 -> 44 | AB18: =U18+5 -> 47 | AF18: =INDEX(A:G,MATCH(AG18,C:C,0),1) -> 67 | AG18: 1400/04/23 | AH18: 16 | AI18: 594918000000 | AJ18: 592836000000 | AK18: =AI18-AJ18 -> 2082000000 | AL18: 0.7 | AM18: 0.55 | AN18: 0.1 | AO18: 0.4 | AP18: 0.9 | AQ18: =H18 -> 0.67 | AR18: 0.79 | AS18: =I18 -> 0.11 | AT18: =AT17+1.6% -> 0.21 | AU18: =J18 -> 0.04 | AV18: =AV17+2.8% -> 0.17 | AW18: =K18 -> 0 | AX18: 0 | AY18: =L18 -> 0 | AZ18: 0 | BA18: =M18 -> 0 | BB18: 0 | BC18: =N18 -> 0 | BD18: 0 | BE18: 67 | BF18: 1400/04/23 | BG18: 16 | BH18: 0.77 | BI18: 0.55 | BJ18: 0.62 | BK18: 0.64
A19: 17 | B19: 44041 | C19: =TEXT(B19,"[$-fa-IR,16]yyyy/mm/dd") -> 1399/05/08 | D19: 0.136 | E19: 0.03976 | F19: =IF($F$2=A19,E19,NA()) -> #N/A | G19: ="تاریخ: "&C19&CHAR(10)&"درصد پیشرفت برنامه ای: "&ROUND(D19*100,2)&"%"&CHAR(10)&"درصد پیشرفت واقعی: "&ROUND(E19*100,2)&"%" -> تاریخ: 1399/05/08 درصد پیشرفت برنامه ای: 13.6% درصد پیشرفت واقعی: 3.98% | H19: =H18+2% -> 0.69 | I19: 0.11 | J19: =J18+3.2% -> 0.072 | K19: 0 | L19: 0 | M19: 0 | N19: 0 | O19: =U18 -> 42 | P19: 43 | Q19: 44 | R19: 42 | S19: 43 | T19: 45 | U19: 45 | V19: =O19+3 -> 45 | W19: =P19+4 -> 47 | X19: =Q19+4 -> 48 | Y19: =R19+1 -> 43 | Z19: =S19+3 -> 46 | AA19: =T19+1 -> 46 | AB19: =U19+5 -> 50 | AF19: =INDEX(A:G,MATCH(AG19,C:C,0),1) -> 71 | AG19: 1400/05/20 | AH19: 17 | AI19: 675718000000 | AJ19: 673353000000 | AK19: =AI19-AJ19 -> 2365000000 | AL19: 0.4 | AM19: 0.69 | AN19: 0.5 | AO19: 0.2 | AP19: 0.4 | AQ19: =H19 -> 0.69 | AR19: 0.83 | AS19: =I19 -> 0.11 | AT19: =AT18+1% -> 0.22 | AU19: =J19 -> 0.072 | AV19: =AV18+2.8% -> 0.198 | AW19: =K19 -> 0 | AX19: 0 | AY19: =L19 -> 0 | AZ19: 0 | BA19: =M19 -> 0 | BB19: 0 | BC19: =N19 -> 0 | BD19: 0 | BE19: 71 | BF19: 1400/05/20 | BG19: 17 | BH19: 0.2 | BI19: 0.6 | BJ19: 0.4 | BK19: 0.65
A20: 18 | B20: 44048 | C20: =TEXT(B20,"[$-fa-IR,16]yyyy/mm/dd") -> 1399/05/15 | D20: 0.143 | E20: 0.04368 | F20: =IF($F$2=A20,E20,NA()) -> #N/A | G20: ="تاریخ: "&C20&CHAR(10)&"درصد پیشرفت برنامه ای: "&ROUND(D20*100,2)&"%"&CHAR(10)&"درصد پیشرفت واقعی: "&ROUND(E20*100,2)&"%" -> تاریخ: 1399/05/15 درصد پیشرفت برنامه ای: 14.3% درصد پیشرفت واقعی: 4.37% | H20: =H19+2% -> 0.71 | I20: 0.11 | J20: =J19+3.2% -> 0.104 | K20: 0 | L20: 0 | M20: 0 | N20: 0 | O20: =U19 -> 45 | P20: 46 | Q20: 45 | R20: 46 | S20: 47 | T20: 47 | U20: 46 | V20: =O20+3 -> 48 | W20: =P20+4 -> 50 | X20: =Q20+4 -> 49 | Y20: =R20+1 -> 47 | Z20: =S20+3 -> 50 | AA20: =T20+1 -> 48 | AB20: =U20+5 -> 51 | AF20: =INDEX(A:G,MATCH(AG20,C:C,0),1) -> 75 | AG20: 1400/06/17 | AH20: 18 | AI20: 719860000000 | AJ20: 717340000000 | AK20: =AI20-AJ20 -> 2520000000 | AL20: 0.35 | AM20: 0.4 | AN20: 0.9 | AO20: 0.8 | AP20: 0.2 | AQ20: =H20 -> 0.71 | AR20: 0.85 | AS20: =I20 -> 0.11 | AT20: =AT19+1% -> 0.23 | AU20: =J20 -> 0.104 | AV20: =AV19+2.8% -> 0.226 | AW20: =K20 -> 0 | AX20: 0 | AY20: =L20 -> 0 | AZ20: 0 | BA20: =M20 -> 0 | BB20: 0 | BC20: =N20 -> 0 | BD20: 0 | BE20: 75 | BF20: 1400/06/17 | BG20: 18 | BH20: 0.45 | BI20: 0.45 | BJ20: 0.55 | BK20: 0.62
A21: 19 | B21: 44055 | C21: =TEXT(B21,"[$-fa-IR,16]yyyy/mm/dd") -> 1399/05/22 | D21: 0.15 | E21: 0.0476 | F21: =IF($F$2=A21,E21,NA()) -> #N/A | G21: ="تاریخ: "&C21&CHAR(10)&"درصد پیشرفت برنامه ای: "&ROUND(D21*100,2)&"%"&CHAR(10)&"درصد پیشرفت واقعی: "&ROUND(E21*100,2)&"%" -> تاریخ: 1399/05/22 درصد پیشرفت برنامه ای: 15% درصد پیشرفت واقعی: 4.76% | H21: =H20+2% -> 0.73 | I21: 0.11 | J21: =J20+3.2% -> 0.136 | K21: 0 | L21: 0 | M21: 0 | N21: 0 | O21: =U20 -> 46 | P21: 47 | Q21: 47 | R21: 46 | S21: 45 | T21: 46 | U21: 47 | V21: =O21+3 -> 49 | W21: =P21+4 -> 51 | X21: =Q21+4 -> 51 | Y21: =R21+1 -> 47 | Z21: =S21+3 -> 48 | AA21: =T21+1 -> 47 | AB21: =U21+5 -> 52 | AF21: =INDEX(A:G,MATCH(AG21,C:C,0),1) -> 79 | AG21: 1400/07/14 | AH21: 19 | AI21: 765525000000 | AJ21: 762846000000 | AK21: =AI21-AJ21 -> 2679000000 | AL21: 0.85 | AM21: 0.8 | AN21: 0.5 | AO21: 0.6 | AP21: 0.6 | AQ21: =H21 -> 0.73 | AR21: 0.89 | AS21: =I21 -> 0.11 | AT21: =AT20+1% -> 0.24 | AU21: =J21 -> 0.136 | AV21: =AV20+2.8% -> 0.254 | AW21: =K21 -> 0 | AX21: 0 | AY21: =L21 -> 0 | AZ21: 0 | BA21: =M21 -> 0 | BB21: 0 | BC21: =N21 -> 0 | BD21: 0 | BE21: 79 | BF21: 1400/07/14 | BG21: 19 | BH21: 0.52 | BI21: 0.77 | BJ21: 0.6 | BK21: 0.4
A22: 20 | B22: 44062 | C22: =TEXT(B22,"[$-fa-IR,16]yyyy/mm/dd") -> 1399/05/29 | D22: 0.157 | E22: 0.05432 | F22: =IF($F$2=A22,E22,NA()) -> #N/A | G22: ="تاریخ: "&C22&CHAR(10)&"درصد پیشرفت برنامه ای: "&ROUND(D22*100,2)&"%"&CHAR(10)&"درصد پیشرفت واقعی: "&ROUND(E22*100,2)&"%" -> تاریخ: 1399/05/29 درصد پیشرفت برنامه ای: 15.7% درصد پیشرفت واقعی: 5.43% | H22: =H21+2% -> 0.75 | I22: 0.11 | J22: =J21+3.2% -> 0.168 | K22: 0 | L22: 0 | M22: 0 | N22: 0 | O22: =U21 -> 47 | P22: 43 | Q22: 44 | R22: 42 | S22: 43 | T22: 45 | U22: 45 | V22: =O22+3 -> 50 | W22: =P22+4 -> 47 | X22: =Q22+4 -> 48 | Y22: =R22+1 -> 43 | Z22: =S22+3 -> 46 | AA22: =T22+1 -> 46 | AB22: =U22+5 -> 50 | AF22: =INDEX(A:G,MATCH(AG22,C:C,0),1) -> 83 | AG22: 1400/08/12 | AH22: 20 | AI22: 765525000000 | AJ22: 762846000000 | AK22: =AI22-AJ22 -> 2679000000 | AL22: 0.9 | AM22: 0.95 | AN22: 0.8 | AO22: 0.7 | AP22: 0.1 | AQ22: =H22 -> 0.75 | AR22: 0.92 | AS22: =I22 -> 0.11 | AT22: =AT21+1% -> 0.25 | AU22: =J22 -> 0.168 | AV22: =AV21+2.8% -> 0.282 | AW22: =K22 -> 0 | AX22: 0 | AY22: =L22 -> 0 | AZ22: 0 | BA22: =M22 -> 0 | BB22: 0 | BC22: =N22 -> 0 | BD22: 0 | BE22: 83 | BF22: 1400/08/12 | BG22: 20 | BH22: 0.62 | BI22: 0.4 | BJ22: 0.45 | BK22: 0.55
A23: 21 | B23: 44069 | C23: =TEXT(B23,"[$-fa-IR,16]yyyy/mm/dd") -> 1399/06/05 | D23: 0.164 | E23: 0.06104 | F23: =IF($F$2=A23,E23,NA()) -> #N/A | G23: ="تاریخ: "&C23&CHAR(10)&"درصد پیشرفت برنامه ای: "&ROUND(D23*100,2)&"%"&CHAR(10)&"درصد پیشرفت واقعی: "&ROUND(E23*100,2)&"%" -> تاریخ: 1399/06/05 درصد پیشرفت برنامه ای: 16.4% درصد پیشرفت واقعی: 6.1% | H23: =H22+2% -> 0.77 | I23: 0.11 | J23: =J22+3.2% -> 0.2 | K23: 0 | L23: 0 | M23: 0 | N23: 0 | O23: =U22 -> 45 | P23: 46 | Q23: 45 | R23: 46 | S23: 47 | T23: 47 | U23: 46 | V23: =O23+3 -> 48 | W23: =P23+4 -> 50 | X23: =Q23+4 -> 49 | Y23: =R23+1 -> 47 | Z23: =S23+3 -> 50 | AA23: =T23+1 -> 48 | AB23: =U23+5 -> 51 | AF23: =INDEX(A:G,MATCH(AG23,C:C,0),1) -> 87 | AG23: 1400/09/10 | AH23: 21 | AI23: 765525000000 | AJ23: 762846000000 | AK23: =AI23-AJ23 -> 2679000000 | AL23: 0.7 | AM23: 0.68 | AN23: 0.5 | AO23: 0.9 | AP23: 0.55 | AQ23: =H23 -> 0.77 | AR23: 0.95 | AS23: =I23 -> 0.11 | AT23: =AT22+1% -> 0.26 | AU23: =J23 -> 0.2 | AV23: =AV22+1.4% -> 0.296 | AW23: =K23 -> 0 | AX23: 0 | AY23: =L23 -> 0 | AZ23: 0 | BA23: =M23 -> 0 | BB23: 0 | BC23: =N23 -> 0 | BD23: 0 | BE23: 87 | BF23: 1400/09/10 | BG23: 21 | BH23: 0.64 | BI23: 0.55 | BJ23: 0.77 | BK23: 0.6
A24: 22 | B24: 44076 | C24: =TEXT(B24,"[$-fa-IR,16]yyyy/mm/dd") -> 1399/06/12 | D24: 0.171 | E24: 0.06776 | F24: =IF($F$2=A24,E24,NA()) -> #N/A | G24: ="تاریخ: "&C24&CHAR(10)&"درصد پیشرفت برنامه ای: "&ROUND(D24*100,2)&"%"&CHAR(10)&"درصد پیشرفت واقعی: "&ROUND(E24*100,2)&"%" -> تاریخ: 1399/06/12 درصد پیشرفت برنامه ای: 17.1% درصد پیشرفت واقعی: 6.78% | H24: =H23+2% -> 0.79 | I24: 0.11 | J24: =J23+3.2% -> 0.232 | K24: 0 | L24: 0 | M24: 0 | N24: 0 | O24: =U23 -> 46 | P24: 47 | Q24: 47 | R24: 46 | S24: 45 | T24: 46 | U24: 47 | V24: =O24+3 -> 49 | W24: =P24+4 -> 51 | X24: =Q24+4 -> 51 | Y24: =R24+1 -> 47 | Z24: =S24+3 -> 48 | AA24: =T24+1 -> 47 | AB24: =U24+5 -> 52 | AF24: =INDEX(A:G,MATCH(AG24,C:C,0),1) -> 91 | AG24: 1400/10/08 | AH24: 22 | AI24: 796437000000 | AJ24: 793649000000 | AK24: =AI24-AJ24 -> 2788000000 | AL24: 0.6 | AM24: 0.5 | AN24: 0.66 | AO24: 0.5 | AP24: 0.9 | AQ24: =H24 -> 0.79 | AR24: 0.99 | AS24: =I24 -> 0.11 | AT24: =AT23+1% -> 0.27 | AU24: =J24 -> 0.232 | AV24: =AV23+1.4% -> 0.31 | AW24: =K24 -> 0 | AX24: 0 | AY24: =L24 -> 0 | AZ24: 0 | BA24: =M24 -> 0 | BB24: 0 | BC24: =N24 -> 0 | BD24: 0 | BE24: 91 | BF24: 1400/10/08 | BG24: 22 | BH24: 0.65 | BI24: 0.6 | BJ24: 0.4 | BK24: 0.45
A25: 23 | B25: 44083 | C25: =TEXT(B25,"[$-fa-IR,16]yyyy/mm/dd") -> 1399/06/19 | D25: 0.178 | E25: 0.07448 | F25: =IF($F$2=A25,E25,NA()) -> #N/A | G25: ="تاریخ: "&C25&CHAR(10)&"درصد پیشرفت برنامه ای: "&ROUND(D25*100,2)&"%"&CHAR(10)&"درصد پیشرفت واقعی: "&ROUND(E25*100,2)&"%" -> تاریخ: 1399/06/19 درصد پیشرفت برنامه ای: 17.8% درصد پیشرفت واقعی: 7.45% | H25: =H24+2% -> 0.81 | I25: 0.11 | J25: =J24+3.2% -> 0.264 | K25: 0 | L25: 0 | M25: 0 | N25: 0 | O25: =U24 -> 47 | P25: 43 | Q25: 44 | R25: 42 | S25: 43 | T25: 45 | U25: 45 | V25: =O25+3 -> 50 | W25: =P25+4 -> 47 | X25: =Q25+4 -> 48 | Y25: =R25+1 -> 43 | Z25: =S25+3 -> 46 | AA25: =T25+1 -> 46 | AB25: =U25+5 -> 50 | AF25: =INDEX(A:G,MATCH(AG25,C:C,0),1) -> 95 | AG25: 1400/11/06 | AH25: 23 | AI25: 824199000000 | AJ25: 821314000000 | AK25: =AI25-AJ25 -> 2885000000 | AL25: 0.55 | AM25: 0.62 | AN25: 0.78 | AO25: 0.42 | AP25: 0.8 | AQ25: =H25 -> 0.81 | AR25: 0.99 | AS25: =I25 -> 0.11 | AT25: =AT24+1% -> 0.28 | AU25: =J25 -> 0.264 | AV25: =AV24+1.9% -> 0.329 | AW25: =K25 -> 0 | AX25: 0 | AY25: =L25 -> 0 | AZ25: 0 | BA25: =M25 -> 0 | BB25: 0 | BC25: =N25 -> 0 | BD25: 0 | BE25: 95 | BF25: 1400/11/06 | BG25: 23 | BH25: 0.62 | BI25: 0.45 | BJ25: 0.55 | BK25: 0.77
A26: 24 | B26: 44090 | C26: =TEXT(B26,"[$-fa-IR,16]yyyy/mm/dd") -> 1399/06/26 | D26: 0.183 | E26: 0.07928 | F26: =IF($F$2=A26,E26,NA()) -> #N/A | G26: ="تاریخ: "&C26&CHAR(10)&"درصد پیشرفت برنامه ای: "&ROUND(D26*100,2)&"%"&CHAR(10)&"درصد پیشرفت واقعی: "&ROUND(E26*100,2)&"%" -> تاریخ: 1399/06/26 درصد پیشرفت برنامه ای: 18.3% درصد پیشرفت واقعی: 7.93% | H26: =H25+2% -> 0.83 | I26: 0.11 | J26: =J25+3.2% -> 0.296 | K26: 0 | L26: 0 | M26: 0 | N26: 0 | O26: =U25 -> 45 | P26: 46 | Q26: 45 | R26: 46 | S26: 47 | T26: 47 | U26: 46 | V26: =O26+3 -> 48 | W26: =P26+4 -> 50 | X26: =Q26+4 -> 49 | Y26: =R26+1 -> 47 | Z26: =S26+3 -> 50 | AA26: =T26+1 -> 48 | AB26: =U26+5 -> 51 | AF26: =INDEX(A:G,MATCH(AG26,C:C,0),1) -> 99 | AG26: 1400/12/04 | AH26: 24 | AI26: 875429000000 | AJ26: 872365000000 | AK26: =AI26-AJ26 -> 3064000000 | AL26: 0.6 | AM26: 0.9 | AN26: 0.5 | AO26: 0.5 | AP26: 0.62 | AQ26: =H26 -> 0.83 | AR26: 1 | AS26: =I26 -> 0.11 | AT26: =AT25+1% -> 0.29 | AU26: =J26 -> 0.296 | AV26: =AV25+1.9% -> 0.348 | AW26: =K26 -> 0 | AX26: 0.03 | AY26: =L26 -> 0 | AZ26: 0 | BA26: =M26 -> 0 | BB26: 0 | BC26: =N26 -> 0 | BD26: 0 | BE26: 99 | BF26: 1400/12/04 | BG26: 24 | BH26: 0.4 | BI26: 0.52 | BJ26: 0.6 | BK26: 0.4
A27: 25 | B27: 44097 | C27: =TEXT(B27,"[$-fa-IR,16]yyyy/mm/dd") -> 1399/07/02 | D27: 0.188 | E27: 0.08408 | F27: =IF($F$2=A27,E27,NA()) -> #N/A | G27: ="تاریخ: "&C27&CHAR(10)&"درصد پیشرفت برنامه ای: "&ROUND(D27*100,2)&"%"&CHAR(10)&"درصد پیشرفت واقعی: "&ROUND(E27*100,2)&"%" -> تاریخ: 1399/07/02 درصد پیشرفت برنامه ای: 18.8% درصد پیشرفت واقعی: 8.41% | H27: =H26+2% -> 0.85 | I27: 0.15 | J27: =J26+3.2% -> 0.328 | K27: 0 | L27: 0 | M27: 0 | N27: 0 | O27: =U26 -> 46 | P27: 43 | Q27: 44 | R27: 42 | S27: 43 | T27: 45 | U27: 45 | V27: =O27+3 -> 49 | W27: =P27+4 -> 47 | X27: =Q27+4 -> 48 | Y27: =R27+1 -> 43 | Z27: =S27+3 -> 46 | AA27: =T27+1 -> 46 | AB27: =U27+5 -> 50 | AF27: =INDEX(A:G,MATCH(AG27,C:C,0),1) -> 103 | AG27: 1401/01/03 | AH27: 25 | AI27: 878795000000 | AJ27: 875719000000 | AK27: =AI27-AJ27 -> 3076000000 | AL27: 0.66 | AM27: 0.7 | AN27: 0.8 | AO27: 0.55 | AP27: 0.5 | AQ27: =H27 -> 0.85 | AR27: 1 | AS27: =I27 -> 0.15 | AT27: =AT26+1% -> 0.3 | AU27: =J27 -> 0.328 | AV27: =AV26+1.9% -> 0.367 | AW27: =K27 -> 0 | AX27: =AX26+3% -> 0.06 | AY27: =L27 -> 0 | AZ27: 0 | BA27: =M27 -> 0 | BB27: 0 | BC27: =N27 -> 0 | BD27: 0 | BE27: 103 | BF27: 1401/01/03 | BG27: 25 | BH27: 0.55 | BI27: 0.62 | BJ27: 0.45 | BK27: 0.55
A28: 26 | B28: 44104 | C28: =TEXT(B28,"[$-fa-IR,16]yyyy/mm/dd") -> 1399/07/09 | D28: 0.193 | E28: 0.08888 | F28: =IF($F$2=A28,E28,NA()) -> #N/A | G28: ="تاریخ: "&C28&CHAR(10)&"درصد پیشرفت برنامه ای: "&ROUND(D28*100,2)&"%"&CHAR(10)&"درصد پیشرفت واقعی: "&ROUND(E28*100,2)&"%" -> تاریخ: 1399/07/09 درصد پیشرفت برنامه ای: 19.3% درصد پیشرفت واقعی: 8.89% | H28: =H27+2% -> 0.87 | I28: 0.15 | J28: =J27+3.2% -> 0.36 | K28: 0 | L28: 0 | M28: 0 | N28: 0 | O28: =U27 -> 45 | P28: 40 | Q28: 41 | R28: 40 | S28: 42 | T28: 43 | U28: 42 | V28: =O28+3 -> 48 | W28: =P28+4 -> 44 | X28: =Q28+4 -> 45 | Y28: =R28+1 -> 41 | Z28: =S28+3 -> 45 | AA28: =T28+1 -> 44 | AB28: =U28+5 -> 47 | AF28: =INDEX(A:G,MATCH(AG28,C:C,0),1) -> 107 | AG28: 1401/01/31 | AH28: 26 | AI28: 884327000000 | AJ28: 881232000000 | AK28: =AI28-AJ28 -> 3095000000 | AL28: 0.55 | AM28: 0.4 | AN28: 0.4 | AO28: 0.9 | AP28: 0.8 | AQ28: =H28 -> 0.87 | AR28: 1 | AS28: =I28 -> 0.15 | AT28: =AT27+1% -> 0.31 | AU28: =J28 -> 0.36 | AV28: =AV27+1.9% -> 0.386 | AW28: =K28 -> 0 | AX28: =AX27+3% -> 0.09 | AY28: =L28 -> 0 | AZ28: 0 | BA28: =M28 -> 0 | BB28: 0 | BC28: =N28 -> 0 | BD28: 0 | BE28: 107 | BF28: 1401/01/31 | BG28: 26 | BH28: 0.6 | BI28: 0.4 | BJ28: 0.6 | BK28: 0.6
A29: 27 | B29: 44111 | C29: =TEXT(B29,"[$-fa-IR,16]yyyy/mm/dd") -> 1399/07/16 | D29: 0.198 | E29: 0.093885 | F29: =IF($F$2=A29,E29,NA()) -> #N/A | G29: ="تاریخ: "&C29&CHAR(10)&"درصد پیشرفت برنامه ای: "&ROUND(D29*100,2)&"%"&CHAR(10)&"درصد پیشرفت واقعی: "&ROUND(E29*100,2)&"%" -> تاریخ: 1399/07/16 درصد پیشرفت برنامه ای: 19.8% درصد پیشرفت واقعی: 9.39% | H29: =H28+2% -> 0.89 | I29: 0.15 | J29: =J28+3.2% -> 0.392 | K29: 0 | L29: 0 | M29: 0 | N29: 0 | O29: =U28 -> 42 | P29: 36 | Q29: 37 | R29: 36 | S29: 38 | T29: 36 | U29: 36 | V29: =O29+3 -> 45 | W29: =P29+4 -> 40 | X29: =Q29+4 -> 41 | Y29: =R29+1 -> 37 | Z29: =S29+3 -> 41 | AA29: =T29+1 -> 37 | AB29: =U29+5 -> 41 | AF29: =INDEX(A:G,MATCH(AG29,C:C,0),1) -> 111 | AG29: 1401/02/28 | AH29: 27 | AI29: 896133000000 | AJ29: 892997000000 | AK29: =AI29-AJ29 -> 3136000000 | AL29: 0.7 | AM29: 0.55 | AN29: 0.1 | AO29: 0.4 | AP29: 0.9 | AQ29: =H29 -> 0.89 | AR29: 1 | AS29: =I29 -> 0.15 | AT29: =AT28+1% -> 0.32 | AU29: =J29 -> 0.392 | AV29: =AV28+1.9% -> 0.405 | AW29: =K29 -> 0 | AX29: =AX28+3% -> 0.12 | AY29: =L29 -> 0 | AZ29: 0 | BA29: =M29 -> 0 | BB29: 0 | BC29: =N29 -> 0 | BD29: 0 | BE29: 111 | BF29: 1401/02/28 | BG29: 27 | BH29: 0.45 | BI29: 0.55 | BJ29: 0.45 | BK29: 0.45
A30: 28 | B30: 44118 | C30: =TEXT(B30,"[$-fa-IR,16]yyyy/mm/dd") -> 1399/07/23 | D30: 0.207 | E30: 0.102894 | F30: =IF($F$2=A30,E30,NA()) -> #N/A | G30: ="تاریخ: "&C30&CHAR(10)&"درصد پیشرفت برنامه ای: "&ROUND(D30*100,2)&"%"&CHAR(10)&"درصد پیشرفت واقعی: "&ROUND(E30*100,2)&"%" -> تاریخ: 1399/07/23 درصد پیشرفت برنامه ای: 20.7% درصد پیشرفت واقعی: 10.29% | H30: =H29+2% -> 0.91 | I30: 0.15 | J30: =J29+3.2% -> 0.424 | K30: 0 | L30: 0 | M30: 0 | N30: 0 | O30: =U29 -> 36 | P30: 22 | Q30: 22 | R30: 23 | S30: 21 | T30: 22 | U30: 24 | V30: =O30+3 -> 39 | W30: =P30+4 -> 26 | X30: =Q30+4 -> 26 | Y30: =R30+1 -> 24 | Z30: =S30+3 -> 24 | AA30: =T30+1 -> 23 | AB30: =U30+5 -> 29 | AF30: =INDEX(A:G,MATCH(AG30,C:C,0),1) -> 115 | AG30: 1401/03/25 | AH30: 28 | AI30: 921963000000 | AJ30: 918736000000 | AK30: =AI30-AJ30 -> 3227000000 | AL30: 0.4 | AM30: 0.69 | AN30: 0.5 | AO30: 0.2 | AP30: 0.4 | AQ30: =H30 -> 0.91 | AR30: 1 | AS30: =I30 -> 0.15 | AT30: =AT29+1% -> 0.33 | AU30: =J30 -> 0.424 | AV30: =AV29+1.9% -> 0.424 | AW30: =K30 -> 0 | AX30: =AX29+3% -> 0.15 | AY30: =L30 -> 0 | AZ30: 0 | BA30: =M30 -> 0 | BB30: 0 | BC30: =N30 -> 0 | BD30: 0 | BE30: 115 | BF30: 1401/03/25 | BG30: 28 | BH30: 0.77 | BI30: 0.6 | BJ30: 0.77 | BK30: 0.77
A31: 29 | B31: 44125 | C31: =TEXT(B31,"[$-fa-IR,16]yyyy/mm/dd") -> 1399/07/30 | D31: 0.216 | E31: 0.111903 | F31: =IF($F$2=A31,E31,NA()) -> #N/A | G31: ="تاریخ: "&C31&CHAR(10)&"درصد پیشرفت برنامه ای: "&ROUND(D31*100,2)&"%"&CHAR(10)&"درصد پیشرفت واقعی: "&ROUND(E31*100,2)&"%" -> تاریخ: 1399/07/30 درصد پیشرفت برنامه ای: 21.6% درصد پیشرفت واقعی: 11.19% | H31: =H30+2% -> 0.93 | I31: 0.15 | J31: =J30+3.2% -> 0.456 | K31: 0 | L31: 0 | M31: 0 | N31: 0 | O31: =U30 -> 24 | P31: 23 | Q31: 24 | R31: 23 | S31: 25 | T31: 25 | U31: 26 | V31: =O31+3 -> 27 | W31: =P31+4 -> 27 | X31: =Q31+4 -> 28 | Y31: =R31+1 -> 24 | Z31: =S31+3 -> 28 | AA31: =T31+1 -> 26 | AB31: =U31+5 -> 31 | AF31: =INDEX(A:G,MATCH(AG31,C:C,0),1) -> 119 | AG31: 1401/04/22 | AH31: 29 | AI31: 936828000000 | AJ31: 933549000000 | AK31: =AI31-AJ31 -> 3279000000 | AL31: 0.35 | AM31: 0.4 | AN31: 0.9 | AO31: 0.8 | AP31: 0.2 | AQ31: =H31 -> 0.93 | AR31: 1 | AS31: =I31 -> 0.15 | AT31: =AT30+1% -> 0.34 | AU31: =J31 -> 0.456 | AV31: =AV30+2.9% -> 0.453 | AW31: =K31 -> 0 | AX31: =AX30+3% -> 0.18 | AY31: =L31 -> 0 | AZ31: 0 | BA31: =M31 -> 0 | BB31: 0 | BC31: =N31 -> 0 | BD31: 0 | BE31: 119 | BF31: 1401/04/22 | BG31: 29 | BH31: 0.2 | BI31: 0.45 | BJ31: 0.4 | BK31: 0.2
A32: 30 | B32: 44132 | C32: =TEXT(B32,"[$-fa-IR,16]yyyy/mm/dd") -> 1399/08/07 | D32: 0.225 | E32: 0.120912 | F32: =IF($F$2=A32,E32,NA()) -> #N/A | G32: ="تاریخ: "&C32&CHAR(10)&"درصد پیشرفت برنامه ای: "&ROUND(D32*100,2)&"%"&CHAR(10)&"درصد پیشرفت واقعی: "&ROUND(E32*100,2)&"%" -> تاریخ: 1399/08/07 درصد پیشرفت برنامه ای: 22.5% درصد پیشرفت واقعی: 12.09% | H32: =H31+2% -> 0.95 | I32: 0.15 | J32: =J31+3.2% -> 0.488 | K32: 0 | L32: 0 | M32: 0 | N32: 0 | O32: =U31 -> 26 | P32: 25 | Q32: 25 | R32: 26 | S32: 26 | T32: 25 | U32: 25 | V32: =O32+3 -> 29 | W32: =P32+4 -> 29 | X32: =Q32+4 -> 29 | Y32: =R32+1 -> 27 | Z32: =S32+3 -> 29 | AA32: =T32+1 -> 26 | AB32: =U32+5 -> 30 | AF32: =INDEX(A:G,MATCH(AG32,C:C,0),1) -> 123 | AG32: 1401/05/19 | AH32: 30 | AI32: 968045000000 | AJ32: 964657000000 | AK32: =AI32-AJ32 -> 3388000000 | AL32: 0.85 | AM32: 0.8 | AN32: 0.5 | AO32: 0.6 | AP32: 0.6 | AQ32: =H32 -> 0.95 | AR32: 1 | AS32: =I32 -> 0.15 | AT32: =AT31+1% -> 0.35 | AU32: =J32 -> 0.488 | AV32: =AV31+2.9% -> 0.482 | AW32: =K32 -> 0 | AX32: =AX31+3% -> 0.21 | AY32: =L32 -> 0 | AZ32: 0 | BA32: =M32 -> 0 | BB32: 0 | BC32: =N32 -> 0 | BD32: 0 | BE32: 123 | BF32: 1401/05/19 | BG32: 30 | BH32: 0.45 | BI32: 0.77 | BJ32: 0.55 | BK32: 0.45
A33: 31 | B33: 44139 | C33: =TEXT(B33,"[$-fa-IR,16]yyyy/mm/dd") -> 1399/08/14 | D33: 0.234 | E33: 0.129921 | F33: =IF($F$2=A33,E33,NA()) -> #N/A | G33: ="تاریخ: "&C33&CHAR(10)&"درصد پیشرفت برنامه ای: "&ROUND(D33*100,2)&"%"&CHAR(10)&"درصد پیشرفت واقعی: "&ROUND(E33*100,2)&"%" -> تاریخ: 1399/08/14 درصد پیشرفت برنامه ای: 23.4% درصد پیشرفت واقعی: 12.99% | H33: =H32+2% -> 0.97 | I33: 0.15 | J33: =J32+3.2% -> 0.52 | K33: 0 | L33: 0 | M33: 0 | N33: 0 | O33: =U32 -> 25 | P33: 15 | Q33: 15 | R33: 18 | S33: 17 | T33: 18 | U33: 19 | V33: =O33+3 -> 28 | W33: =P33+4 -> 19 | X33: =Q33+4 -> 19 | Y33: =R33+1 -> 19 | Z33: =S33+3 -> 20 | AA33: =T33+1 -> 19 | AB33: =U33+5 -> 24 | AF33: =INDEX(A:G,MATCH(AG33,C:C,0),1) -> 127 | AG33: 1401/06/16 | AH33: 31 | AI33: 994802000000 | AJ33: 991320000000 | AK33: =AI33-AJ33 -> 3482000000 | AL33: 0.9 | AM33: 0.95 | AN33: 0.8 | AO33: 0.7 | AP33: 0.1 | AQ33: =H33 -> 0.97 | AR33: 1 | AS33: =I33 -> 0.15 | AT33: 0.35 | AU33: =J33 -> 0.52 | AV33: =AV32+2.9% -> 0.511 | AW33: =K33 -> 0 | AX33: =AX32+3% -> 0.24 | AY33: =L33 -> 0 | AZ33: 0 | BA33: =M33 -> 0 | BB33: 0 | BC33: =N33 -> 0 | BD33: 0 | BE33: 127 | BF33: 1401/06/16 | BG33: 31 | BH33: 0.52 | BI33: 0.4 | BJ33: 0.6 | BK33: 0.52
A34: 32 | B34: 44146 | C34: =TEXT(B34,"[$-fa-IR,16]yyyy/mm/dd") -> 1399/08/21 | D34: 0.243 | E34: 0.13893 | F34: =IF($F$2=A34,E34,NA()) -> #N/A | G34: ="تاریخ: "&C34&CHAR(10)&"درصد پیشرفت برنامه ای: "&ROUND(D34*100,2)&"%"&CHAR(10)&"درصد پیشرفت واقعی: "&ROUND(E34*100,2)&"%" -> تاریخ: 1399/08/21 درصد پیشرفت برنامه ای: 24.3% درصد پیشرفت واقعی: 13.89% | H34: =H33+2% -> 0.99 | I34: =I33+1% -> 0.16 | J34: =J33+3.2% -> 0.552 | K34: =J17 -> 0.03 | L34: 0 | M34: 0 | N34: 0 | O34: =U33 -> 19 | P34: 19 | Q34: 17 | R34: 17 | S34: 19 | T34: 20 | U34: 21 | V34: =O34+3 -> 22 | W34: =P34+4 -> 23 | X34: =Q34+4 -> 21 | Y34: =R34+1 -> 18 | Z34: =S34+3 -> 22 | AA34: =T34+1 -> 21 | AB34: =U34+5 -> 26 | AF34: =INDEX(A:G,MATCH(AG34,C:C,0),1) -> 131 | AG34: 1401/07/13 | AH34: 32 | AI34: 1003991000000 | AJ34: 1000477000000 | AK34: =AI34-AJ34 -> 3514000000 | AL34: 0.7 | AM34: 0.68 | AN34: 0.5 | AO34: 0.9 | AP34: 0.55 | AQ34: =H34 -> 0.99 | AR34: 1 | AS34: =I34 -> 0.16 | AT34: 0.35 | AU34: =J34 -> 0.552 | AV34: =AV33+3.4% -> 0.545 | AW34: =K34 -> 0.03 | AX34: =AX33+3% -> 0.27 | AY34: =L34 -> 0 | AZ34: 0 | BA34: =M34 -> 0 | BB34: 0 | BC34: =N34 -> 0 | BD34: 0 | BE34: 131 | BF34: 1401/07/13 | BG34: 32 | BH34: 0.62 | BI34: 0.55 | BJ34: 0.45 | BK34: 0.62
A35: 33 | B35: 44153 | C35: =TEXT(B35,"[$-fa-IR,16]yyyy/mm/dd") -> 1399/08/28 | D35: 0.252 | E35: 0.147939 | F35: =IF($F$2=A35,E35,NA()) -> #N/A | G35: ="تاریخ: "&C35&CHAR(10)&"درصد پیشرفت برنامه ای: "&ROUND(D35*100,2)&"%"&CHAR(10)&"درصد پیشرفت واقعی: "&ROUND(E35*100,2)&"%" -> تاریخ: 1399/08/28 درصد پیشرفت برنامه ای: 25.2% درصد پیشرفت واقعی: 14.79% | H35: 1 | I35: 0.16 | J35: =J34+3.2% -> 0.584 | K35: =J18 -> 0.04 | L35: 0 | M35: 0 | N35: 0 | O35: =U34 -> 21 | P35: 22 | Q35: 22 | R35: 23 | S35: 21 | T35: 22 | U35: 24 | V35: =O35+3 -> 24 | W35: =P35+4 -> 26 | X35: =Q35+4 -> 26 | Y35: =R35+1 -> 24 | Z35: =S35+3 -> 24 | AA35: =T35+1 -> 23 | AB35: =U35+5 -> 29 | AF35: =INDEX(A:G,MATCH(AG35,C:C,0),1) -> 135 | AG35: 1401/08/11 | AH35: 33 | AI35: 1040747000000 | AJ35: 1037104000000 | AK35: =AI35-AJ35 -> 3643000000 | AL35: 0.6 | AM35: 0.5 | AN35: 0.66 | AO35: 0.5 | AP35: 0.9 | AQ35: =H35 -> 1 | AR35: 1 | AS35: =I35 -> 0.16 | AT35: 0.35 | AU35: =J35 -> 0.584 | AV35: =AV34+3.4% -> 0.579 | AW35: =K35 -> 0.04 | AX35: =AX34+3% -> 0.3 | AY35: =L35 -> 0 | AZ35: 0 | BA35: =M35 -> 0 | BB35: 0 | BC35: =N35 -> 0 | BD35: 0 | BE35: 135 | BF35: 1401/08/11 | BG35: 33 | BH35: 0.64 | BI35: 0.6 | BJ35: 0.52 | BK35: 0.4
A36: 34 | B36: 44160 | C36: =TEXT(B36,"[$-fa-IR,16]yyyy/mm/dd") -> 1399/09/05 | D36: 0.261 | E36: 0.156948 | F36: =IF($F$2=A36,E36,NA()) -> #N/A | G36: ="تاریخ: "&C36&CHAR(10)&"درصد پیشرفت برنامه ای: "&ROUND(D36*100,2)&"%"&CHAR(10)&"درصد پیشرفت واقعی: "&ROUND(E36*100,2)&"%" -> تاریخ: 1399/09/05 درصد پیشرفت برنامه ای: 26.1% درصد پیشرفت واقعی: 15.69% | H36: 1 | I36: 0.16 | J36: =J35+3.2% -> 0.616 | K36: =J19 -> 0.072 | L36: 0 | M36: 0 | N36: 0 | O36: =U35 -> 24 | P36: 15 | Q36: 15 | R36: 18 | S36: 17 | T36: 18 | U36: 19 | V36: =O36+3 -> 27 | W36: =P36+4 -> 19 | X36: =Q36+4 -> 19 | Y36: =R36+1 -> 19 | Z36: =S36+3 -> 20 | AA36: =T36+1 -> 19 | AB36: =U36+5 -> 24 | AF36: =INDEX(A:G,MATCH(AG36,C:C,0),1) -> 139 | AG36: 1401/09/09 | AH36: 34 | AI36: 1083629000000 | AJ36: 1079836000000 | AK36: =AI36-AJ36 -> 3793000000 | AL36: 0.55 | AM36: 0.62 | AN36: 0.78 | AO36: 0.42 | AP36: 0.8 | AQ36: =H36 -> 1 | AR36: 1 | AS36: =I36 -> 0.16 | AT36: 0.35 | AU36: =J36 -> 0.616 | AV36: =AV35+3.4% -> 0.613 | AW36: =K36 -> 0.072 | AX36: =AX35+3% -> 0.33 | AY36: =L36 -> 0 | AZ36: 0 | BA36: =M36 -> 0 | BB36: 0 | BC36: =N36 -> 0 | BD36: 0 | BE36: 139 | BF36: 1401/09/09 | BG36: 34 | BH36: 0.65 | BI36: 0.45 | BJ36: 0.62 | BK36: 0.55
A37: 35 | B37: 44167 | C37: =TEXT(B37,"[$-fa-IR,16]yyyy/mm/dd") -> 1399/09/12 | D37: 0.271 | E37: 0.166958 | F37: =IF($F$2=A37,E37,NA()) -> #N/A | G37: ="تاریخ: "&C37&CHAR(10)&"درصد پیشرفت برنامه ای: "&ROUND(D37*100,2)&"%"&CHAR(10)&"درصد پیشرفت واقعی: "&ROUND(E37*100,2)&"%" -> تاریخ: 1399/09/12 درصد پیشرفت برنامه ای: 27.1% درصد پیشرفت واقعی: 16.7% | H37: 1 | I37: 0.16 | J37: =J36+3.2% -> 0.648 | K37: =J20 -> 0.104 | L37: 0 | M37: 0 | N37: 0 | O37: =U36 -> 19 | P37: 19 | Q37: 17 | R37: 17 | S37: 19 | T37: 20 | U37: 21 | V37: =O37+3 -> 22 | W37: =P37+4 -> 23 | X37: =Q37+4 -> 21 | Y37: =R37+1 -> 18 | Z37: =S37+3 -> 22 | AA37: =T37+1 -> 21 | AB37: =U37+5 -> 26 | AF37: =INDEX(A:G,MATCH(AG37,C:C,0),1) -> 143 | AG37: 1401/10/07 | AH37: 35 | AI37: 1113896000000 | AJ37: 1109997000000 | AK37: =AI37-AJ37 -> 3899000000 | AL37: 0.6 | AM37: 0.9 | AN37: 0.5 | AO37: 0.5 | AP37: 0.62 | AQ37: =H37 -> 1 | AR37: 1 | AS37: =I37 -> 0.16 | AT37: 0.35 | AU37: =J37 -> 0.648 | AV37: =AV36+3.4% -> 0.647 | AW37: =K37 -> 0.104 | AX37: =AX36+3% -> 0.36 | AY37: =L37 -> 0 | AZ37: 0 | BA37: =M37 -> 0 | BB37: 0 | BC37: =N37 -> 0 | BD37: 0 | BE37: 143 | BF37: 1401/10/07 | BG37: 35 | BH37: 0.62 | BI37: 0.52 | BJ37: 0.4 | BK37: 0.6
A38: 36 | B38: 44174 | C38: =TEXT(B38,"[$-fa-IR,16]yyyy/mm/dd") -> 1399/09/19 | D38: 0.281 | E38: 0.176968 | F38: =IF($F$2=A38,E38,NA()) -> #N/A | G38: ="تاریخ: "&C38&CHAR(10)&"درصد پیشرفت برنامه ای: "&ROUND(D38*100,2)&"%"&CHAR(10)&"درصد پیشرفت واقعی: "&ROUND(E38*100,2)&"%" -> تاریخ: 1399/09/19 درصد پیشرفت برنامه ای: 28.1% درصد پیشرفت واقعی: 17.7% | H38: 1 | I38: 0.17 | J38: =J37+3.2% -> 0.68 | K38: =J21 -> 0.136 | L38: 0 | M38: 0 | N38: 0 | O38: =U37 -> 21 | P38: 15 | Q38: 15 | R38: 18 | S38: 17 | T38: 18 | U38: 19 | V38: =O38+3 -> 24 | W38: =P38+4 -> 19 | X38: =Q38+4 -> 19 | Y38: =R38+1 -> 19 | Z38: =S38+3 -> 20 | AA38: =T38+1 -> 19 | AB38: =U38+5 -> 24 | AF38: =INDEX(A:G,MATCH(AG38,C:C,0),1) -> 147 | AG38: 1401/11/05 | AH38: 36 | AI38: 1127948000000 | AJ38: 1124000000000 | AK38: =AI38-AJ38 -> 3948000000 | AL38: 0.66 | AM38: 0.7 | AN38: 0.8 | AO38: 0.55 | AP38: 0.5 | AQ38: =H38 -> 1 | AR38: 1 | AS38: =I38 -> 0.17 | AT38: 0.35 | AU38: =J38 -> 0.68 | AV38: =AV37+3.4% -> 0.681 | AW38: =K38 -> 0.136 | AX38: =AX37+3% -> 0.39 | AY38: =L38 -> 0 | AZ38: 0 | BA38: =M38 -> 0 | BB38: 0 | BC38: =N38 -> 0 | BD38: 0 | BE38: 147 | BF38: 1401/11/05 | BG38: 36 | BH38: 0.4 | BI38: 0.62 | BJ38: 0.55 | BK38: 0.45
A39: 37 | B39: 44181 | C39: =TEXT(B39,"[$-fa-IR,16]yyyy/mm/dd") -> 1399/09/26 | D39: 0.291 | E39: 0.186978 | F39: =IF($F$2=A39,E39,NA()) -> #N/A | G39: ="تاریخ: "&C39&CHAR(10)&"درصد پیشرفت برنامه ای: "&ROUND(D39*100,2)&"%"&CHAR(10)&"درصد پیشرفت واقعی: "&ROUND(E39*100,2)&"%" -> تاریخ: 1399/09/26 درصد پیشرفت برنامه ای: 29.1% درصد پیشرفت واقعی: 18.7% | H39: 1 | I39: 0.17 | J39: =J38+3.2% -> 0.712 | K39: =J22 -> 0.168 | L39: 0 | M39: 0 | N39: 0 | O39: =U38 -> 19 | P39: 19 | Q39: 17 | R39: 17 | S39: 19 | T39: 20 | U39: 21 | V39: =O39+3 -> 22 | W39: =P39+4 -> 23 | X39: =Q39+4 -> 21 | Y39: =R39+1 -> 18 | Z39: =S39+3 -> 22 | AA39: =T39+1 -> 21 | AB39: =U39+5 -> 26 | AF39: =INDEX(A:G,MATCH(AG39,C:C,0),1) -> 151 | AG39: 1401/12/03 | AH39: 37 | AI39: 1135274000000 | AJ39: 1131301000000 | AK39: =AI39-AJ39 -> 3973000000 | AL39: 0.55 | AM39: 0.4 | AN39: 0.4 | AO39: 0.9 | AP39: 0.8 | AQ39: =H39 -> 1 | AR39: 1 | AS39: =I39 -> 0.17 | AT39: 0.35 | AU39: =J39 -> 0.712 | AV39: =AV38+3.9% -> 0.72 | AW39: =K39 -> 0.168 | AX39: =AX38+2% -> 0.41 | AY39: =L39 -> 0 | AZ39: 0 | BA39: =M39 -> 0 | BB39: 0 | BC39: =N39 -> 0 | BD39: 0 | BE39: 151 | BF39: 1401/12/03 | BG39: 37 | BH39: 0.55 | BI39: 0.4 | BJ39: 0.6 | BK39: 0.77
A40: 38 | B40: 44188 | C40: =TEXT(B40,"[$-fa-IR,16]yyyy/mm/dd") -> 1399/10/03 | D40: 0.301 | E40: 0.196988 | F40: =IF($F$2=A40,E40,NA()) -> #N/A | G40: ="تاریخ: "&C40&CHAR(10)&"درصد پیشرفت برنامه ای: "&ROUND(D40*100,2)&"%"&CHAR(10)&"درصد پیشرفت واقعی: "&ROUND(E40*100,2)&"%" -> تاریخ: 1399/10/03 درصد پیشرفت برنامه ای: 30.1% درصد پیشرفت واقعی: 19.7% | H40: 1 | I40: 0.17 | J40: =J39+3.2% -> 0.744 | K40: =J23 -> 0.2 | L40: 0 | M40: 0 | N40: 0 | O40: =U39 -> 21 | P40: 15 | Q40: 15 | R40: 18 | S40: 14 | T40: 15 | U40: 13 | V40: =O40+3 -> 24 | W40: =P40+4 -> 19 | X40: =Q40+4 -> 19 | Y40: =R40+1 -> 19 | Z40: =S40+3 -> 17 | AA40: =T40+1 -> 16 | AB40: =U40+5 -> 18 | AF40: =INDEX(A:G,MATCH(AG40,C:C,0),1) -> 155 | AG40: 1402/01/02 | AH40: 38 | AI40: 1151384000000 | AJ40: 1147354000000 | AK40: =AI40-AJ40 -> 4030000000 | AL40: 0.7 | AM40: 0.55 | AN40: 0.1 | AO40: 0.4 | AP40: 0.9 | AQ40: =H40 -> 1 | AR40: 1 | AS40: =I40 -> 0.17 | AT40: 0.35 | AU40: =J40 -> 0.744 | AV40: =AV39+3.9% -> 0.759 | AW40: =K40 -> 0.2 | AX40: =AX39+2% -> 0.43 | AY40: =L40 -> 0 | AZ40: 0 | BA40: =M40 -> 0 | BB40: 0 | BC40: =N40 -> 0 | BD40: 0 | BE40: 155 | BF40: 1402/01/02 | BG40: 38 | BH40: 0.6 | BI40: 0.55 | BJ40: 0.45 | BK40: 0.4
...

Sheet Dashboard
A1: 131 | B1: =INDEX(Data!A3:G262,MATCH(Dashboard!A1,Data!A3:A262,0),3) -> 1401/07/13
Q4: شماره | R4: =IFERROR(INDEX(Data!AH:AH,MATCH(Data!F2,Data!AF:AF,1),1),"----") -> 32 | S4: ="شماره: "&R4 -> شماره: 32
Q5: ارسالی | R5: =IFERROR(INDEX(Data!AI:AI,MATCH(Dashboard!$R$4,Data!$AH:$AH,0),1),"----") -> 1003991000000
Q6: تاییدی | R6: =IFERROR(INDEX(Data!AJ:AJ,MATCH(Dashboard!$R$4,Data!$AH:$AH,0),1),"----") -> 1000477000000
Q7: اختلاف | R7: =IFERROR(R5-R6,"----") -> 3514000000
Q21: 180 | R21: {=INDEX(Data!AL:AP,MATCH(Data!F2,Data!A:A,0),)} -> 0.7 | S21: 0.68 | T21: 0.5 | U21: 0.9 | V21: 0.55
Q22: 180
R24: =R21*1.8*100 -> 126 | S24: =S21*1.8*100 -> 122.4 | T24: =T21*1.8*100 -> 90 | U24: =U21*1.8*100 -> 162 | V24: =V21*1.8*100 -> 99
R25: 5 | S25: 5 | T25: 5 | U25: 5 | V25: 5
A26: =INDEX(Data!$H:$M,MATCH($A$1,Data!$A:$A,0),1) -> 1 | B26: =A26*2.7*100 -> 270 | C26: =INDEX(Data!$H:$M,MATCH($A$1,Data!$A:$A,0),2) -> 0.72 | D26: =C26*2.7*100 -> 194.4 | E26: =INDEX(Data!$H:$M,MATCH($A$1,Data!$A:$A,0),3) -> 1 | F26: =E26*2.7*100 -> 270 | G26: =INDEX(Data!$H:$M,MATCH($A$1,Data!$A:$A,0),4) -> 1 | H26: =G26*2.7*100 -> 270 | I26: =INDEX(Data!$H:$M,MATCH($A$1,Data!$A:$A,0),5) -> 1 | J26: =I26*2.7*100 -> 270 | K26: =INDEX(Data!$H:$M,MATCH($A$1,Data!$A:$A,0),6) -> 1 | L26: =K26*2.7*100 -> 270 | M26: =INDEX(Data!$H:$N,MATCH($A$1,Data!$A:$A,0),7) -> 1 | N26: =M26*2.7*100 -> 270 | R26: =360-R24-R25 -> 229 | S26: =360-S24-S25 -> 232.6 | T26: =360-T24-T25 -> 265 | U26: =360-U24-U25 -> 193 | V26: =360-V24-V25 -> 256
B27: 5 | D27: 5 | F27: 5 | H27: 5 | J27: 5 | L27: 5 | N27: 5
B28: =270-(B26+B27) -> -5 | D28: =270-(D26+D27) -> 70.6 | F28: =270-(F26+F27) -> -5 | H28: =270-(H26+H27) -> -5 | J28: =270-(J26+J27) -> -5 | L28: =270-(L26+L27) -> -5 | N28: =270-(N26+N27) -> -5
B29: 90 | D29: 90 | F29: 90 | H29: 90 | J29: 90 | L29: 90 | N29: 90
R31: واقعی | T31: برنامه ای
Q32: درصد پیشرفت مهندسی | R32: =INDEX(Data!$AQ:$BD,MATCH(Data!$F$2,Data!$A:$A,0),2)*100 -> 100 | T32: =INDEX(Data!$AQ:$BD,MATCH(Data!$F$2,Data!$A:$A,0),1)*100 -> 100 | Y32: پیمانکار 1 | Z32: پیمانکار 2 | AA32: پیمانکار 3 | AB32: پیمانکار 4
X33: بالا | Y33: =IF(Y36<=Y35,NA(),Y36) -> #N/A | Z33: =IF(Z36<=Z35,NA(),Z36) -> 0.77 | AA33: =IF(AA36<=AA35,NA(),AA36) -> #N/A | AB33: =IF(AB36<=AB35,NA(),AB36) -> #N/A
Q34: درصد پیشرفت خرید | R34: =INDEX(Data!$AQ:$BD,MATCH(Data!$F$2,Data!$A:$A,0),4)*100 -> 82.2 | T34: =INDEX(Data!$AQ:$BD,MATCH(Data!$F$2,Data!$A:$A,0),3)*100 -> 72 | X34: پایین | Y34: =IF(Y36<=Y35,Y36,NA()) -> 0.2 | Z34: =IF(Z36<=Z35,Z36,NA()) -> #N/A | AA34: =IF(AA36<=AA35,AA36,NA()) -> 0.4 | AB34: =IF(AB36<=AB35,AB36,NA()) -> 0.45
X35: POINT | Y35: 0.5 | Z35: 0.5 | AA35: 0.5 | AB35: 0.5
Q36: درصد پیشرفت فونداسیون | R36: =INDEX(Data!$AQ:$BD,MATCH(Data!$F$2,Data!$A:$A,0),6)*100 -> 100 | T36: =INDEX(Data!$AQ:$BD,MATCH(Data!$F$2,Data!$A:$A,0),5)*100 -> 100 | Y36: =INDEX(Data!$BE:$BK,MATCH(Data!$F$2,Data!$BG:$BG,11),4) -> 0.2 | Z36: =INDEX(Data!$BE:$BK,MATCH(Data!$F$2,Data!$BG:$BG,11),5) -> 0.77 | AA36: =INDEX(Data!$BE:$BK,MATCH(Data!$F$2,Data!$BG:$BG,11),6) -> 0.4 | AB36: =INDEX(Data!$BE:$BK,MATCH(Data!$F$2,Data!$BG:$BG,11),7) -> 0.45
Q38: درصد پیشرفت ساخت | R38: =INDEX(Data!$AQ:$BD,MATCH(Data!$F$2,Data!$A:$A,0),8)*100 -> 100 | T38: =INDEX(Data!$AQ:$BD,MATCH(Data!$F$2,Data!$A:$A,0),7)*100 -> 100
Q40: درصد پیشرفت نصب | R40: =INDEX(Data!$AQ:$BD,MATCH(Data!$F$2,Data!$A:$A,0),10)*100 -> 100 | T40: =INDEX(Data!$AQ:$BD,MATCH(Data!$F$2,Data!$A:$A,0),9)*100 -> 100
Q42: درصد پیشرفت سفت کاری | R42: =INDEX(Data!$AQ:$BD,MATCH(Data!$F$2,Data!$A:$A,0),12)*100 -> 100 | T42: =INDEX(Data!$AQ:$BD,MATCH(Data!$F$2,Data!$A:$A,0),11)*100 -> 100
Q44: درصد پیشرفت نازک کاری | R44: =INDEX(Data!$AQ:$BD,MATCH(Data!$F$2,Data!$A:$A,0),14)*100 -> 100 | T44: =INDEX(Data!$AQ:$BD,MATCH(Data!$F$2,Data!$A:$A,0),13)*100 -> 100
